2018-11-15 10:21:51,442 ERROR: Exception on /edit_profile [POST] [in c:\users\jmiller.ad\microblog\venv\lib\site-packages\flask\app.py:1761]
Traceback (most recent call last):
  File "c:\users\jmiller.ad\microblog\venv\lib\site-packages\sqlalchemy\engine\base.py", line 1193, in _execute_context
    context)
  File "c:\users\jmiller.ad\microblog\venv\lib\site-packages\sqlalchemy\engine\default.py", line 509, in do_execute
    cursor.execute(statement, parameters)
sqlite3.IntegrityError: UNIQUE constraint failed: user.username

The above exception was the direct cause of the following exception:

Traceback (most recent call last):
  File "c:\users\jmiller.ad\microblog\venv\lib\site-packages\flask\app.py", line 2292, in wsgi_app
    response = self.full_dispatch_request()
  File "c:\users\jmiller.ad\microblog\venv\lib\site-packages\flask\app.py", line 1815, in full_dispatch_request
    rv = self.handle_user_exception(e)
  File "c:\users\jmiller.ad\microblog\venv\lib\site-packages\flask\app.py", line 1718, in handle_user_exception
    reraise(exc_type, exc_value, tb)
  File "c:\users\jmiller.ad\microblog\venv\lib\site-packages\flask\_compat.py", line 35, in reraise
    raise value
  File "c:\users\jmiller.ad\microblog\venv\lib\site-packages\flask\app.py", line 1813, in full_dispatch_request
    rv = self.dispatch_request()
  File "c:\users\jmiller.ad\microblog\venv\lib\site-packages\flask\app.py", line 1799, in dispatch_request
    return self.view_functions[rule.endpoint](**req.view_args)
  File "c:\users\jmiller.ad\microblog\venv\lib\site-packages\flask_login\utils.py", line 261, in decorated_view
    return func(*args, **kwargs)
  File "C:\Users\JMILLER.AD\melly\app\routes.py", line 90, in edit_profile
    db.session.commit()
  File "c:\users\jmiller.ad\microblog\venv\lib\site-packages\sqlalchemy\orm\scoping.py", line 153, in do
    return getattr(self.registry(), name)(*args, **kwargs)
  File "c:\users\jmiller.ad\microblog\venv\lib\site-packages\sqlalchemy\orm\session.py", line 943, in commit
    self.transaction.commit()
  File "c:\users\jmiller.ad\microblog\venv\lib\site-packages\sqlalchemy\orm\session.py", line 467, in commit
    self._prepare_impl()
  File "c:\users\jmiller.ad\microblog\venv\lib\site-packages\sqlalchemy\orm\session.py", line 447, in _prepare_impl
    self.session.flush()
  File "c:\users\jmiller.ad\microblog\venv\lib\site-packages\sqlalchemy\orm\session.py", line 2254, in flush
    self._flush(objects)
  File "c:\users\jmiller.ad\microblog\venv\lib\site-packages\sqlalchemy\orm\session.py", line 2381, in _flush
    transaction.rollback(_capture_exception=True)
  File "c:\users\jmiller.ad\microblog\venv\lib\site-packages\sqlalchemy\util\langhelpers.py", line 66, in __exit__
    compat.reraise(exc_type, exc_value, exc_tb)
  File "c:\users\jmiller.ad\microblog\venv\lib\site-packages\sqlalchemy\util\compat.py", line 249, in reraise
    raise value
  File "c:\users\jmiller.ad\microblog\venv\lib\site-packages\sqlalchemy\orm\session.py", line 2345, in _flush
    flush_context.execute()
  File "c:\users\jmiller.ad\microblog\venv\lib\site-packages\sqlalchemy\orm\unitofwork.py", line 395, in execute
    rec.execute(self)
  File "c:\users\jmiller.ad\microblog\venv\lib\site-packages\sqlalchemy\orm\unitofwork.py", line 560, in execute
    uow
  File "c:\users\jmiller.ad\microblog\venv\lib\site-packages\sqlalchemy\orm\persistence.py", line 177, in save_obj
    mapper, table, update)
  File "c:\users\jmiller.ad\microblog\venv\lib\site-packages\sqlalchemy\orm\persistence.py", line 768, in _emit_update_statements
    execute(statement, multiparams)
  File "c:\users\jmiller.ad\microblog\venv\lib\site-packages\sqlalchemy\engine\base.py", line 948, in execute
    return meth(self, multiparams, params)
  File "c:\users\jmiller.ad\microblog\venv\lib\site-packages\sqlalchemy\sql\elements.py", line 269, in _execute_on_connection
    return connection._execute_clauseelement(self, multiparams, params)
  File "c:\users\jmiller.ad\microblog\venv\lib\site-packages\sqlalchemy\engine\base.py", line 1060, in _execute_clauseelement
    compiled_sql, distilled_params
  File "c:\users\jmiller.ad\microblog\venv\lib\site-packages\sqlalchemy\engine\base.py", line 1200, in _execute_context
    context)
  File "c:\users\jmiller.ad\microblog\venv\lib\site-packages\sqlalchemy\engine\base.py", line 1413, in _handle_dbapi_exception
    exc_info
  File "c:\users\jmiller.ad\microblog\venv\lib\site-packages\sqlalchemy\util\compat.py", line 265, in raise_from_cause
    reraise(type(exception), exception, tb=exc_tb, cause=cause)
  File "c:\users\jmiller.ad\microblog\venv\lib\site-packages\sqlalchemy\util\compat.py", line 248, in reraise
    raise value.with_traceback(tb)
  File "c:\users\jmiller.ad\microblog\venv\lib\site-packages\sqlalchemy\engine\base.py", line 1193, in _execute_context
    context)
  File "c:\users\jmiller.ad\microblog\venv\lib\site-packages\sqlalchemy\engine\default.py", line 509, in do_execute
    cursor.execute(statement, parameters)
sqlalchemy.exc.IntegrityError: (sqlite3.IntegrityError) UNIQUE constraint failed: user.username [SQL: 'UPDATE user SET username=? WHERE user.id = ?'] [parameters: ('karina', 1)] (Background on this error at: http://sqlalche.me/e/gkpj)
2018-11-20 11:50:07,015 INFO: Microblog startup [in C:\Users\JMILLER.AD\melly\app\__init__.py:49]
2018-11-20 15:39:52,328 INFO: Microblog startup [in C:\Users\JMILLER.AD\melly\app\__init__.py:49]
2018-11-20 15:39:58,736 ERROR: Exception on /explore [GET] [in c:\users\jmiller.ad\microblog\venv\lib\site-packages\flask\app.py:1761]
Traceback (most recent call last):
  File "c:\users\jmiller.ad\microblog\venv\lib\site-packages\flask\app.py", line 2292, in wsgi_app
    response = self.full_dispatch_request()
  File "c:\users\jmiller.ad\microblog\venv\lib\site-packages\flask\app.py", line 1815, in full_dispatch_request
    rv = self.handle_user_exception(e)
  File "c:\users\jmiller.ad\microblog\venv\lib\site-packages\flask\app.py", line 1718, in handle_user_exception
    reraise(exc_type, exc_value, tb)
  File "c:\users\jmiller.ad\microblog\venv\lib\site-packages\flask\_compat.py", line 35, in reraise
    raise value
  File "c:\users\jmiller.ad\microblog\venv\lib\site-packages\flask\app.py", line 1813, in full_dispatch_request
    rv = self.dispatch_request()
  File "c:\users\jmiller.ad\microblog\venv\lib\site-packages\flask\app.py", line 1799, in dispatch_request
    return self.view_functions[rule.endpoint](**req.view_args)
  File "c:\users\jmiller.ad\microblog\venv\lib\site-packages\flask_login\utils.py", line 261, in decorated_view
    return func(*args, **kwargs)
  File "C:\Users\JMILLER.AD\melly\app\routes.py", line 140, in explore
    next_url=next_url, prev_url=prev_url)
  File "c:\users\jmiller.ad\microblog\venv\lib\site-packages\flask\templating.py", line 135, in render_template
    context, ctx.app)
  File "c:\users\jmiller.ad\microblog\venv\lib\site-packages\flask\templating.py", line 117, in _render
    rv = template.render(context)
  File "c:\users\jmiller.ad\microblog\venv\lib\site-packages\jinja2\environment.py", line 1008, in render
    return self.environment.handle_exception(exc_info, True)
  File "c:\users\jmiller.ad\microblog\venv\lib\site-packages\jinja2\environment.py", line 780, in handle_exception
    reraise(exc_type, exc_value, tb)
  File "c:\users\jmiller.ad\microblog\venv\lib\site-packages\jinja2\_compat.py", line 37, in reraise
    raise value.with_traceback(tb)
  File "C:\Users\JMILLER.AD\melly\app\templates\base.html", line 49, in template
    {% endblock %}
  File "c:\users\jmiller.ad\microblog\venv\lib\site-packages\jinja2\environment.py", line 1005, in render
    return concat(self.root_render_func(self.new_context(vars)))
  File "C:\Users\JMILLER.AD\melly\app\templates\index.html", line 1, in top-level template code
    {% extends "base.html" %}
  File "c:\users\jmiller.ad\microblog\venv\lib\site-packages\jinja2\environment.py", line 780, in handle_exception
    reraise(exc_type, exc_value, tb)
  File "c:\users\jmiller.ad\microblog\venv\lib\site-packages\jinja2\_compat.py", line 37, in reraise
    raise value.with_traceback(tb)
  File "C:\Users\JMILLER.AD\melly\app\templates\base.html", line 49, in template
    {% endblock %}
  File "c:\users\jmiller.ad\microblog\venv\lib\site-packages\jinja2\environment.py", line 497, in _parse
    return Parser(self, source, name, encode_filename(filename)).parse()
  File "c:\users\jmiller.ad\microblog\venv\lib\site-packages\jinja2\parser.py", line 901, in parse
    result = nodes.Template(self.subparse(), lineno=1)
  File "c:\users\jmiller.ad\microblog\venv\lib\site-packages\jinja2\parser.py", line 883, in subparse
    rv = self.parse_statement()
  File "c:\users\jmiller.ad\microblog\venv\lib\site-packages\jinja2\parser.py", line 130, in parse_statement
    return getattr(self, 'parse_' + self.stream.current.value)()
  File "c:\users\jmiller.ad\microblog\venv\lib\site-packages\jinja2\parser.py", line 268, in parse_block
    node.body = self.parse_statements(('name:endblock',), drop_needle=True)
  File "c:\users\jmiller.ad\microblog\venv\lib\site-packages\jinja2\parser.py", line 170, in parse_statements
    self.fail_eof(end_tokens)
  File "c:\users\jmiller.ad\microblog\venv\lib\site-packages\jinja2\parser.py", line 104, in fail_eof
    return self._fail_ut_eof(None, stack, lineno)
  File "c:\users\jmiller.ad\microblog\venv\lib\site-packages\jinja2\parser.py", line 90, in _fail_ut_eof
    self.fail(' '.join(message), lineno)
  File "c:\users\jmiller.ad\microblog\venv\lib\site-packages\jinja2\parser.py", line 59, in fail
    raise exc(msg, lineno, self.name, self.filename)
jinja2.exceptions.TemplateSyntaxError: Unexpected end of template. Jinja was looking for the following tags: 'endblock'. The innermost block that needs to be closed is 'block'.
2018-11-20 15:42:21,739 INFO: Microblog startup [in C:\Users\JMILLER.AD\melly\app\__init__.py:49]
2018-11-20 15:58:03,279 INFO: Microblog startup [in C:\Users\JMILLER.AD\melly\app\__init__.py:51]
